Workbook
Name a_coupon: Inputs!$B$15
Name a_notional: Inputs!$B$14
Name b_coupon: Inputs!$B$17
Name b_notional: Inputs!$B$16
Name case_number: Case!$B$2
Name coupon: Inputs!$B$10
Name face: Inputs!$B$9
Name lgd: Inputs!$B$12
Name pd_annual: Inputs!$B$11
Name rho: Inputs!$B$13

Sheet Inputs
A1: Miniproject 3 (Part 1) - Simplified CDO analysis
A2: FRE 6103 Valuation for Financial Engineering (NYU Tandon) | Raj Pawar (rsp9234) and Michael Brick (mb11311)
A3: Yellow cells are inputs; everything else in the workbook is a formula. All amounts are in $ millions. The case to display is chosen on the Case sheet.
A5: Parameter | B5: Value | C5: Note
A6: Number of bonds | B6: 10 | C6: Fixed by the layout of the sheets (10 columns per block).
A7: Years to maturity | B7: 5 | C7: Fixed by the layout (20 quarterly columns).
A8: Payments per year | B8: 4 | C8: Quarterly.
A9: Face value per bond ($MM) | B9: 10 | C9: Given.
A10: Coupon rate, annual | B10: 0.06 | C10: Given. Paid quarterly: coupon / 4 x face.
A11: Default probability, annual (pi) | B11: 0.04 | C11: Given. Default time in years t = ln(1 - u) / ln(1 - pi).
A12: Loss given default (lambda) | B12: 0.6 | C12: Given. BIS model: 1 - LGD of every promised payment is always paid.
A13: Correlation between default dates | B13: 0.2 | C13: Given. Applied to the normals through the Cholesky factor.
A14: Class A notional ($MM) | B14: 20 | C14: Given.
A15: Class A coupon, annual | B15: 0.02 | C15: Given. Paid quarterly, principal at maturity.
A16: Class B notional ($MM) | B16: 10 | C16: Given.
A17: Class B coupon, annual | B17: 0.04 | C17: Given. Paid quarterly, principal at maturity.
... A19: Risk-free rate | B19: 0.01 | C19: Given. Not used until Part 2.
A20: Seed of the fixed random numbers | B20: 6103
A23: Promised cash flows ($MM)
A24: Quarter | B24: One bond | C24: Pool (10 bonds) | D24: Due to Class A | E24: Due to Class B
A25: 1 | B25: =face*coupon/4+IF(A25=20,face,0) -> 0.15 | C25: =10*B25 -> 1.5 | D25: =a_notional*a_coupon/4+IF(A25=20,a_notional,0) -> 0.1 | E25: =b_notional*b_coupon/4+IF(A25=20,b_notional,0) -> 0.1
A26: 2 | B26: =face*coupon/4+IF(A26=20,face,0) -> 0.15 | C26: =10*B26 -> 1.5 | D26: =a_notional*a_coupon/4+IF(A26=20,a_notional,0) -> 0.1 | E26: =b_notional*b_coupon/4+IF(A26=20,b_notional,0) -> 0.1
A27: 3 | B27: =face*coupon/4+IF(A27=20,face,0) -> 0.15 | C27: =10*B27 -> 1.5 | D27: =a_notional*a_coupon/4+IF(A27=20,a_notional,0) -> 0.1 | E27: =b_notional*b_coupon/4+IF(A27=20,b_notional,0) -> 0.1
A28: 4 | B28: =face*coupon/4+IF(A28=20,face,0) -> 0.15 | C28: =10*B28 -> 1.5 | D28: =a_notional*a_coupon/4+IF(A28=20,a_notional,0) -> 0.1 | E28: =b_notional*b_coupon/4+IF(A28=20,b_notional,0) -> 0.1
A29: 5 | B29: =face*coupon/4+IF(A29=20,face,0) -> 0.15 | C29: =10*B29 -> 1.5 | D29: =a_notional*a_coupon/4+IF(A29=20,a_notional,0) -> 0.1 | E29: =b_notional*b_coupon/4+IF(A29=20,b_notional,0) -> 0.1
A30: 6 | B30: =face*coupon/4+IF(A30=20,face,0) -> 0.15 | C30: =10*B30 -> 1.5 | D30: =a_notional*a_coupon/4+IF(A30=20,a_notional,0) -> 0.1 | E30: =b_notional*b_coupon/4+IF(A30=20,b_notional,0) -> 0.1
A31: 7 | B31: =face*coupon/4+IF(A31=20,face,0) -> 0.15 | C31: =10*B31 -> 1.5 | D31: =a_notional*a_coupon/4+IF(A31=20,a_notional,0) -> 0.1 | E31: =b_notional*b_coupon/4+IF(A31=20,b_notional,0) -> 0.1
A32: 8 | B32: =face*coupon/4+IF(A32=20,face,0) -> 0.15 | C32: =10*B32 -> 1.5 | D32: =a_notional*a_coupon/4+IF(A32=20,a_notional,0) -> 0.1 | E32: =b_notional*b_coupon/4+IF(A32=20,b_notional,0) -> 0.1
A33: 9 | B33: =face*coupon/4+IF(A33=20,face,0) -> 0.15 | C33: =10*B33 -> 1.5 | D33: =a_notional*a_coupon/4+IF(A33=20,a_notional,0) -> 0.1 | E33: =b_notional*b_coupon/4+IF(A33=20,b_notional,0) -> 0.1
A34: 10 | B34: =face*coupon/4+IF(A34=20,face,0) -> 0.15 | C34: =10*B34 -> 1.5 | D34: =a_notional*a_coupon/4+IF(A34=20,a_notional,0) -> 0.1 | E34: =b_notional*b_coupon/4+IF(A34=20,b_notional,0) -> 0.1
A35: 11 | B35: =face*coupon/4+IF(A35=20,face,0) -> 0.15 | C35: =10*B35 -> 1.5 | D35: =a_notional*a_coupon/4+IF(A35=20,a_notional,0) -> 0.1 | E35: =b_notional*b_coupon/4+IF(A35=20,b_notional,0) -> 0.1
A36: 12 | B36: =face*coupon/4+IF(A36=20,face,0) -> 0.15 | C36: =10*B36 -> 1.5 | D36: =a_notional*a_coupon/4+IF(A36=20,a_notional,0) -> 0.1 | E36: =b_notional*b_coupon/4+IF(A36=20,b_notional,0) -> 0.1
... A44: 20 | B44: =face*coupon/4+IF(A44=20,face,0) -> 10.15 | C44: =10*B44 -> 101.5 | D44: =a_notional*a_coupon/4+IF(A44=20,a_notional,0) -> 20.1 | E44: =b_notional*b_coupon/4+IF(A44=20,b_notional,0) -> 10.1
A45: Total | B45: =SUM(B25:B44) -> 13 | C45: =SUM(C25:C44) -> 130 | D45: =SUM(D25:D44) -> 22 | E45: =SUM(E25:E44) -> 12

Sheet Case
A1: Case viewer
A2: Case to display (1 to 1000) | B2: 5 | C2: Type any case number in the yellow cell. Everything on this sheet follows it.
A5: Bond | B5: Random normal z | C5: Correlated normal x | D5: Uniform u | E5: Default time (years) | F5: Default quarter (21 = none) | G5: Status | H5: Total cash received ($MM)
A6: Bond 1 | B6: =INDEX(Random!$B$18:$K$1017,case_number,1) -> -1.8599871 | C6: =INDEX(Defaults!$B$18:$K$1017,case_number,1) -> -1.8599871 | D6: =INDEX(Defaults!$M$18:$V$1017,case_number,1) -> 0.031443676 | E6: =INDEX(Defaults!$X$18:$AG$1017,case_number,1) -> 0.78263304 | F6: =INDEX(Defaults!$AI$18:$AR$1017,case_number,1) -> 4 | G6: =IF(F6<=20,"defaults in quarter "&F6,"survives") -> defaults in quarter 4 | H6: =SUM(B20:B39) -> 5.47
A7: Bond 2 | B7: =INDEX(Random!$B$18:$K$1017,case_number,2) -> 0.75061757 | C7: =INDEX(Defaults!$B$18:$K$1017,case_number,2) -> 0.36345459 | D7: =INDEX(Defaults!$M$18:$V$1017,case_number,2) -> 0.64186734 | E7: =INDEX(Defaults!$X$18:$AG$1017,case_number,2) -> 25.154376 | F7: =INDEX(Defaults!$AI$18:$AR$1017,case_number,2) -> 21 | G7: =IF(F7<=20,"defaults in quarter "&F7,"survives") -> survives | H7: =SUM(C20:C39) -> 13
A8: Bond 3 | B8: =INDEX(Random!$B$18:$K$1017,case_number,3) -> 0.2224588 | C8: =INDEX(Defaults!$B$18:$K$1017,case_number,3) -> -0.034506468 | D8: =INDEX(Defaults!$M$18:$V$1017,case_number,3) -> 0.48623664 | E8: =INDEX(Defaults!$X$18:$AG$1017,case_number,3) -> 16.314551 | F8: =INDEX(Defaults!$AI$18:$AR$1017,case_number,3) -> 21 | G8: =IF(F8<=20,"defaults in quarter "&F8,"survives") -> survives | H8: =SUM(D20:D39) -> 13
A9: Bond 4 | B9: =INDEX(Random!$B$18:$K$1017,case_number,4) -> -0.78341897 | C9: =INDEX(Defaults!$B$18:$K$1017,case_number,4) -> -0.96781167 | D9: =INDEX(Defaults!$M$18:$V$1017,case_number,4) -> 0.16656922 | E9: =INDEX(Defaults!$X$18:$AG$1017,case_number,4) -> 4.4633935 | F9: =INDEX(Defaults!$AI$18:$AR$1017,case_number,4) -> 18 | G9: =IF(F9<=20,"defaults in quarter "&F9,"survives") -> defaults in quarter 18 | H9: =SUM(E20:E39) -> 6.73
A10: Bond 5 | B10: =INDEX(Random!$B$18:$K$1017,case_number,5) -> -1.5263177 | C10: =INDEX(Defaults!$B$18:$K$1017,case_number,5) -> -1.7603485 | D10: =INDEX(Defaults!$M$18:$V$1017,case_number,5) -> 0.039174371 | E10: =INDEX(Defaults!$X$18:$AG$1017,case_number,5) -> 0.97894124 | F10: =INDEX(Defaults!$AI$18:$AR$1017,case_number,5) -> 4 | G10: =IF(F10<=20,"defaults in quarter "&F10,"survives") -> defaults in quarter 4 | H10: =SUM(F20:F39) -> 5.47
A11: Bond 6 | B11: =INDEX(Random!$B$18:$K$1017,case_number,6) -> -0.78531154 | C11: =INDEX(Defaults!$B$18:$K$1017,case_number,6) -> -1.2136432 | D11: =INDEX(Defaults!$M$18:$V$1017,case_number,6) -> 0.11244201 | E11: =INDEX(Defaults!$X$18:$AG$1017,case_number,6) -> 2.921989 | F11: =INDEX(Defaults!$AI$18:$AR$1017,case_number,6) -> 12 | G11: =IF(F11<=20,"defaults in quarter "&F11,"survives") -> defaults in quarter 12 | H11: =SUM(G20:G39) -> 6.19
A12: Bond 7 | B12: =INDEX(Random!$B$18:$K$1017,case_number,7) -> -0.83463465 | C12: =INDEX(Defaults!$B$18:$K$1017,case_number,7) -> -1.3302409 | D12: =INDEX(Defaults!$M$18:$V$1017,case_number,7) -> 0.091719452 | E12: =INDEX(Defaults!$X$18:$AG$1017,case_number,7) -> 2.3566211 | F12: =INDEX(Defaults!$AI$18:$AR$1017,case_number,7) -> 10 | G12: =IF(F12<=20,"defaults in quarter "&F12,"survives") -> defaults in quarter 10 | H12: =SUM(H20:H39) -> 6.01
A13: Bond 8 | B13: =INDEX(Random!$B$18:$K$1017,case_number,8) -> -0.079703706 | C13: =INDEX(Defaults!$B$18:$K$1017,case_number,8) -> -0.69292121 | D13: =INDEX(Defaults!$M$18:$V$1017,case_number,8) -> 0.2441795 | E13: =INDEX(Defaults!$X$18:$AG$1017,case_number,8) -> 6.8578561 | F13: =INDEX(Defaults!$AI$18:$AR$1017,case_number,8) -> 21 | G13: =IF(F13<=20,"defaults in quarter "&F13,"survives") -> survives | H13: =SUM(I20:I39) -> 13
A14: Bond 9 | B14: =INDEX(Random!$B$18:$K$1017,case_number,9) -> -0.83237702 | C14: =INDEX(Defaults!$B$18:$K$1017,case_number,9) -> -1.3995679 | D14: =INDEX(Defaults!$M$18:$V$1017,case_number,9) -> 0.080821381 | E14: =INDEX(Defaults!$X$18:$AG$1017,case_number,9) -> 2.0644463 | F14: =INDEX(Defaults!$AI$18:$AR$1017,case_number,9) -> 9 | G14: =IF(F14<=20,"defaults in quarter "&F14,"survives") -> defaults in quarter 9 | H14: =SUM(J20:J39) -> 5.92
A15: Bond 10 | B15: =INDEX(Random!$B$18:$K$1017,case_number,10) -> 0.28584576 | C15: =INDEX(Defaults!$B$18:$K$1017,case_number,10) -> -0.41895534 | D15: =INDEX(Defaults!$M$18:$V$1017,case_number,10) -> 0.33762439 | E15: =INDEX(Defaults!$X$18:$AG$1017,case_number,10) -> 10.0907 | F15: =INDEX(Defaults!$AI$18:$AR$1017,case_number,10) -> 21 | G15: =IF(F15<=20,"defaults in quarter "&F15,"survives") -> survives | H15: =SUM(K20:K39) -> 13
A16: Bonds defaulting within 5 years | F16: =COUNTIF(F6:F15,"<=20") -> 6
A19: Quarter | B19: Bond 1 | C19: Bond 2 | D19: Bond 3 | E19: Bond 4 | F19: Bond 5 | G19: Bond 6 | H19: Bond 7 | I19: Bond 8 | J19: Bond 9 | K19: Bond 10 | L19: Pool | M19: Class A | N19: Class B | O19: Equity | P19: Pool promised
A20: 1 | B20: =Inputs!$B$25*IF($A20>=$F$6,1-lgd,1) -> 0.15 | C20: =Inputs!$B$25*IF($A20>=$F$7,1-lgd,1) -> 0.15 | D20: =Inputs!$B$25*IF($A20>=$F$8,1-lgd,1) -> 0.15 | E20: =Inputs!$B$25*IF($A20>=$F$9,1-lgd,1) -> 0.15 | F20: =Inputs!$B$25*IF($A20>=$F$10,1-lgd,1) -> 0.15 | G20: =Inputs!$B$25*IF($A20>=$F$11,1-lgd,1) -> 0.15 | H20: =Inputs!$B$25*IF($A20>=$F$12,1-lgd,1) -> 0.15 | I20: =Inputs!$B$25*IF($A20>=$F$13,1-lgd,1) -> 0.15 | J20: =Inputs!$B$25*IF($A20>=$F$14,1-lgd,1) -> 0.15 | K20: =Inputs!$B$25*IF($A20>=$F$15,1-lgd,1) -> 0.15 | L20: =SUM(B20:K20) -> 1.5 | M20: =MIN(L20,Inputs!$D$25) -> 0.1 | N20: =MIN(L20-M20,Inputs!$E$25) -> 0.1 | O20: =L20-M20-N20 -> 1.3 | P20: =Inputs!$C$25 -> 1.5
A21: 2 | B21: =Inputs!$B$26*IF($A21>=$F$6,1-lgd,1) -> 0.15 | C21: =Inputs!$B$26*IF($A21>=$F$7,1-lgd,1) -> 0.15 | D21: =Inputs!$B$26*IF($A21>=$F$8,1-lgd,1) -> 0.15 | E21: =Inputs!$B$26*IF($A21>=$F$9,1-lgd,1) -> 0.15 | F21: =Inputs!$B$26*IF($A21>=$F$10,1-lgd,1) -> 0.15 | G21: =Inputs!$B$26*IF($A21>=$F$11,1-lgd,1) -> 0.15 | H21: =Inputs!$B$26*IF($A21>=$F$12,1-lgd,1) -> 0.15 | I21: =Inputs!$B$26*IF($A21>=$F$13,1-lgd,1) -> 0.15 | J21: =Inputs!$B$26*IF($A21>=$F$14,1-lgd,1) -> 0.15 | K21: =Inputs!$B$26*IF($A21>=$F$15,1-lgd,1) -> 0.15 | L21: =SUM(B21:K21) -> 1.5 | M21: =MIN(L21,Inputs!$D$26) -> 0.1 | N21: =MIN(L21-M21,Inputs!$E$26) -> 0.1 | O21: =L21-M21-N21 -> 1.3 | P21: =Inputs!$C$26 -> 1.5
A22: 3 | B22: =Inputs!$B$27*IF($A22>=$F$6,1-lgd,1) -> 0.15 | C22: =Inputs!$B$27*IF($A22>=$F$7,1-lgd,1) -> 0.15 | D22: =Inputs!$B$27*IF($A22>=$F$8,1-lgd,1) -> 0.15 | E22: =Inputs!$B$27*IF($A22>=$F$9,1-lgd,1) -> 0.15 | F22: =Inputs!$B$27*IF($A22>=$F$10,1-lgd,1) -> 0.15 | G22: =Inputs!$B$27*IF($A22>=$F$11,1-lgd,1) -> 0.15 | H22: =Inputs!$B$27*IF($A22>=$F$12,1-lgd,1) -> 0.15 | I22: =Inputs!$B$27*IF($A22>=$F$13,1-lgd,1) -> 0.15 | J22: =Inputs!$B$27*IF($A22>=$F$14,1-lgd,1) -> 0.15 | K22: =Inputs!$B$27*IF($A22>=$F$15,1-lgd,1) -> 0.15 | L22: =SUM(B22:K22) -> 1.5 | M22: =MIN(L22,Inputs!$D$27) -> 0.1 | N22: =MIN(L22-M22,Inputs!$E$27) -> 0.1 | O22: =L22-M22-N22 -> 1.3 | P22: =Inputs!$C$27 -> 1.5
A23: 4 | B23: =Inputs!$B$28*IF($A23>=$F$6,1-lgd,1) -> 0.06 | C23: =Inputs!$B$28*IF($A23>=$F$7,1-lgd,1) -> 0.15 | D23: =Inputs!$B$28*IF($A23>=$F$8,1-lgd,1) -> 0.15 | E23: =Inputs!$B$28*IF($A23>=$F$9,1-lgd,1) -> 0.15 | F23: =Inputs!$B$28*IF($A23>=$F$10,1-lgd,1) -> 0.06 | G23: =Inputs!$B$28*IF($A23>=$F$11,1-lgd,1) -> 0.15 | H23: =Inputs!$B$28*IF($A23>=$F$12,1-lgd,1) -> 0.15 | I23: =Inputs!$B$28*IF($A23>=$F$13,1-lgd,1) -> 0.15 | J23: =Inputs!$B$28*IF($A23>=$F$14,1-lgd,1) -> 0.15 | K23: =Inputs!$B$28*IF($A23>=$F$15,1-lgd,1) -> 0.15 | L23: =SUM(B23:K23) -> 1.32 | M23: =MIN(L23,Inputs!$D$28) -> 0.1 | N23: =MIN(L23-M23,Inputs!$E$28) -> 0.1 | O23: =L23-M23-N23 -> 1.12 | P23: =Inputs!$C$28 -> 1.5
A24: 5 | B24: =Inputs!$B$29*IF($A24>=$F$6,1-lgd,1) -> 0.06 | C24: =Inputs!$B$29*IF($A24>=$F$7,1-lgd,1) -> 0.15 | D24: =Inputs!$B$29*IF($A24>=$F$8,1-lgd,1) -> 0.15 | E24: =Inputs!$B$29*IF($A24>=$F$9,1-lgd,1) -> 0.15 | F24: =Inputs!$B$29*IF($A24>=$F$10,1-lgd,1) -> 0.06 | G24: =Inputs!$B$29*IF($A24>=$F$11,1-lgd,1) -> 0.15 | H24: =Inputs!$B$29*IF($A24>=$F$12,1-lgd,1) -> 0.15 | I24: =Inputs!$B$29*IF($A24>=$F$13,1-lgd,1) -> 0.15 | J24: =Inputs!$B$29*IF($A24>=$F$14,1-lgd,1) -> 0.15 | K24: =Inputs!$B$29*IF($A24>=$F$15,1-lgd,1) -> 0.15 | L24: =SUM(B24:K24) -> 1.32 | M24: =MIN(L24,Inputs!$D$29) -> 0.1 | N24: =MIN(L24-M24,Inputs!$E$29) -> 0.1 | O24: =L24-M24-N24 -> 1.12 | P24: =Inputs!$C$29 -> 1.5
A25: 6 | B25: =Inputs!$B$30*IF($A25>=$F$6,1-lgd,1) -> 0.06 | C25: =Inputs!$B$30*IF($A25>=$F$7,1-lgd,1) -> 0.15 | D25: =Inputs!$B$30*IF($A25>=$F$8,1-lgd,1) -> 0.15 | E25: =Inputs!$B$30*IF($A25>=$F$9,1-lgd,1) -> 0.15 | F25: =Inputs!$B$30*IF($A25>=$F$10,1-lgd,1) -> 0.06 | G25: =Inputs!$B$30*IF($A25>=$F$11,1-lgd,1) -> 0.15 | H25: =Inputs!$B$30*IF($A25>=$F$12,1-lgd,1) -> 0.15 | I25: =Inputs!$B$30*IF($A25>=$F$13,1-lgd,1) -> 0.15 | J25: =Inputs!$B$30*IF($A25>=$F$14,1-lgd,1) -> 0.15 | K25: =Inputs!$B$30*IF($A25>=$F$15,1-lgd,1) -> 0.15 | L25: =SUM(B25:K25) -> 1.32 | M25: =MIN(L25,Inputs!$D$30) -> 0.1 | N25: =MIN(L25-M25,Inputs!$E$30) -> 0.1 | O25: =L25-M25-N25 -> 1.12 | P25: =Inputs!$C$30 -> 1.5
A26: 7 | B26: =Inputs!$B$31*IF($A26>=$F$6,1-lgd,1) -> 0.06 | C26: =Inputs!$B$31*IF($A26>=$F$7,1-lgd,1) -> 0.15 | D26: =Inputs!$B$31*IF($A26>=$F$8,1-lgd,1) -> 0.15 | E26: =Inputs!$B$31*IF($A26>=$F$9,1-lgd,1) -> 0.15 | F26: =Inputs!$B$31*IF($A26>=$F$10,1-lgd,1) -> 0.06 | G26: =Inputs!$B$31*IF($A26>=$F$11,1-lgd,1) -> 0.15 | H26: =Inputs!$B$31*IF($A26>=$F$12,1-lgd,1) -> 0.15 | I26: =Inputs!$B$31*IF($A26>=$F$13,1-lgd,1) -> 0.15 | J26: =Inputs!$B$31*IF($A26>=$F$14,1-lgd,1) -> 0.15 | K26: =Inputs!$B$31*IF($A26>=$F$15,1-lgd,1) -> 0.15 | L26: =SUM(B26:K26) -> 1.32 | M26: =MIN(L26,Inputs!$D$31) -> 0.1 | N26: =MIN(L26-M26,Inputs!$E$31) -> 0.1 | O26: =L26-M26-N26 -> 1.12 | P26: =Inputs!$C$31 -> 1.5
A27: 8 | B27: =Inputs!$B$32*IF($A27>=$F$6,1-lgd,1) -> 0.06 | C27: =Inputs!$B$32*IF($A27>=$F$7,1-lgd,1) -> 0.15 | D27: =Inputs!$B$32*IF($A27>=$F$8,1-lgd,1) -> 0.15 | E27: =Inputs!$B$32*IF($A27>=$F$9,1-lgd,1) -> 0.15 | F27: =Inputs!$B$32*IF($A27>=$F$10,1-lgd,1) -> 0.06 | G27: =Inputs!$B$32*IF($A27>=$F$11,1-lgd,1) -> 0.15 | H27: =Inputs!$B$32*IF($A27>=$F$12,1-lgd,1) -> 0.15 | I27: =Inputs!$B$32*IF($A27>=$F$13,1-lgd,1) -> 0.15 | J27: =Inputs!$B$32*IF($A27>=$F$14,1-lgd,1) -> 0.15 | K27: =Inputs!$B$32*IF($A27>=$F$15,1-lgd,1) -> 0.15 | L27: =SUM(B27:K27) -> 1.32 | M27: =MIN(L27,Inputs!$D$32) -> 0.1 | N27: =MIN(L27-M27,Inputs!$E$32) -> 0.1 | O27: =L27-M27-N27 -> 1.12 | P27: =Inputs!$C$32 -> 1.5
A28: 9 | B28: =Inputs!$B$33*IF($A28>=$F$6,1-lgd,1) -> 0.06 | C28: =Inputs!$B$33*IF($A28>=$F$7,1-lgd,1) -> 0.15 | D28: =Inputs!$B$33*IF($A28>=$F$8,1-lgd,1) -> 0.15 | E28: =Inputs!$B$33*IF($A28>=$F$9,1-lgd,1) -> 0.15 | F28: =Inputs!$B$33*IF($A28>=$F$10,1-lgd,1) -> 0.06 | G28: =Inputs!$B$33*IF($A28>=$F$11,1-lgd,1) -> 0.15 | H28: =Inputs!$B$33*IF($A28>=$F$12,1-lgd,1) -> 0.15 | I28: =Inputs!$B$33*IF($A28>=$F$13,1-lgd,1) -> 0.15 | J28: =Inputs!$B$33*IF($A28>=$F$14,1-lgd,1) -> 0.06 | K28: =Inputs!$B$33*IF($A28>=$F$15,1-lgd,1) -> 0.15 | L28: =SUM(B28:K28) -> 1.23 | M28: =MIN(L28,Inputs!$D$33) -> 0.1 | N28: =MIN(L28-M28,Inputs!$E$33) -> 0.1 | O28: =L28-M28-N28 -> 1.03 | P28: =Inputs!$C$33 -> 1.5
A29: 10 | B29: =Inputs!$B$34*IF($A29>=$F$6,1-lgd,1) -> 0.06 | C29: =Inputs!$B$34*IF($A29>=$F$7,1-lgd,1) -> 0.15 | D29: =Inputs!$B$34*IF($A29>=$F$8,1-lgd,1) -> 0.15 | E29: =Inputs!$B$34*IF($A29>=$F$9,1-lgd,1) -> 0.15 | F29: =Inputs!$B$34*IF($A29>=$F$10,1-lgd,1) -> 0.06 | G29: =Inputs!$B$34*IF($A29>=$F$11,1-lgd,1) -> 0.15 | H29: =Inputs!$B$34*IF($A29>=$F$12,1-lgd,1) -> 0.06 | I29: =Inputs!$B$34*IF($A29>=$F$13,1-lgd,1) -> 0.15 | J29: =Inputs!$B$34*IF($A29>=$F$14,1-lgd,1) -> 0.06 | K29: =Inputs!$B$34*IF($A29>=$F$15,1-lgd,1) -> 0.15 | L29: =SUM(B29:K29) -> 1.14 | M29: =MIN(L29,Inputs!$D$34) -> 0.1 | N29: =MIN(L29-M29,Inputs!$E$34) -> 0.1 | O29: =L29-M29-N29 -> 0.94 | P29: =Inputs!$C$34 -> 1.5
A30: 11 | B30: =Inputs!$B$35*IF($A30>=$F$6,1-lgd,1) -> 0.06 | C30: =Inputs!$B$35*IF($A30>=$F$7,1-lgd,1) -> 0.15 | D30: =Inputs!$B$35*IF($A30>=$F$8,1-lgd,1) -> 0.15 | E30: =Inputs!$B$35*IF($A30>=$F$9,1-lgd,1) -> 0.15 | F30: =Inputs!$B$35*IF($A30>=$F$10,1-lgd,1) -> 0.06 | G30: =Inputs!$B$35*IF($A30>=$F$11,1-lgd,1) -> 0.15 | H30: =Inputs!$B$35*IF($A30>=$F$12,1-lgd,1) -> 0.06 | I30: =Inputs!$B$35*IF($A30>=$F$13,1-lgd,1) -> 0.15 | J30: =Inputs!$B$35*IF($A30>=$F$14,1-lgd,1) -> 0.06 | K30: =Inputs!$B$35*IF($A30>=$F$15,1-lgd,1) -> 0.15 | L30: =SUM(B30:K30) -> 1.14 | M30: =MIN(L30,Inputs!$D$35) -> 0.1 | N30: =MIN(L30-M30,Inputs!$E$35) -> 0.1 | O30: =L30-M30-N30 -> 0.94 | P30: =Inputs!$C$35 -> 1.5
A31: 12 | B31: =Inputs!$B$36*IF($A31>=$F$6,1-lgd,1) -> 0.06 | C31: =Inputs!$B$36*IF($A31>=$F$7,1-lgd,1) -> 0.15 | D31: =Inputs!$B$36*IF($A31>=$F$8,1-lgd,1) -> 0.15 | E31: =Inputs!$B$36*IF($A31>=$F$9,1-lgd,1) -> 0.15 | F31: =Inputs!$B$36*IF($A31>=$F$10,1-lgd,1) -> 0.06 | G31: =Inputs!$B$36*IF($A31>=$F$11,1-lgd,1) -> 0.06 | H31: =Inputs!$B$36*IF($A31>=$F$12,1-lgd,1) -> 0.06 | I31: =Inputs!$B$36*IF($A31>=$F$13,1-lgd,1) -> 0.15 | J31: =Inputs!$B$36*IF($A31>=$F$14,1-lgd,1) -> 0.06 | K31: =Inputs!$B$36*IF($A31>=$F$15,1-lgd,1) -> 0.15 | L31: =SUM(B31:K31) -> 1.05 | M31: =MIN(L31,Inputs!$D$36) -> 0.1 | N31: =MIN(L31-M31,Inputs!$E$36) -> 0.1 | O31: =L31-M31-N31 -> 0.85 | P31: =Inputs!$C$36 -> 1.5
A32: 13 | B32: =Inputs!$B$37*IF($A32>=$F$6,1-lgd,1) -> 0.06 | C32: =Inputs!$B$37*IF($A32>=$F$7,1-lgd,1) -> 0.15 | D32: =Inputs!$B$37*IF($A32>=$F$8,1-lgd,1) -> 0.15 | E32: =Inputs!$B$37*IF($A32>=$F$9,1-lgd,1) -> 0.15 | F32: =Inputs!$B$37*IF($A32>=$F$10,1-lgd,1) -> 0.06 | G32: =Inputs!$B$37*IF($A32>=$F$11,1-lgd,1) -> 0.06 | H32: =Inputs!$B$37*IF($A32>=$F$12,1-lgd,1) -> 0.06 | I32: =Inputs!$B$37*IF($A32>=$F$13,1-lgd,1) -> 0.15 | J32: =Inputs!$B$37*IF($A32>=$F$14,1-lgd,1) -> 0.06 | K32: =Inputs!$B$37*IF($A32>=$F$15,1-lgd,1) -> 0.15 | L32: =SUM(B32:K32) -> 1.05 | M32: =MIN(L32,Inputs!$D$37) -> 0.1 | N32: =MIN(L32-M32,Inputs!$E$37) -> 0.1 | O32: =L32-M32-N32 -> 0.85 | P32: =Inputs!$C$37 -> 1.5
A33: 14 | B33: =Inputs!$B$38*IF($A33>=$F$6,1-lgd,1) -> 0.06 | C33: =Inputs!$B$38*IF($A33>=$F$7,1-lgd,1) -> 0.15 | D33: =Inputs!$B$38*IF($A33>=$F$8,1-lgd,1) -> 0.15 | E33: =Inputs!$B$38*IF($A33>=$F$9,1-lgd,1) -> 0.15 | F33: =Inputs!$B$38*IF($A33>=$F$10,1-lgd,1) -> 0.06 | G33: =Inputs!$B$38*IF($A33>=$F$11,1-lgd,1) -> 0.06 | H33: =Inputs!$B$38*IF($A33>=$F$12,1-lgd,1) -> 0.06 | I33: =Inputs!$B$38*IF($A33>=$F$13,1-lgd,1) -> 0.15 | J33: =Inputs!$B$38*IF($A33>=$F$14,1-lgd,1) -> 0.06 | K33: =Inputs!$B$38*IF($A33>=$F$15,1-lgd,1) -> 0.15 | L33: =SUM(B33:K33) -> 1.05 | M33: =MIN(L33,Inputs!$D$38) -> 0.1 | N33: =MIN(L33-M33,Inputs!$E$38) -> 0.1 | O33: =L33-M33-N33 -> 0.85 | P33: =Inputs!$C$38 -> 1.5
A34: 15 | B34: =Inputs!$B$39*IF($A34>=$F$6,1-lgd,1) -> 0.06 | C34: =Inputs!$B$39*IF($A34>=$F$7,1-lgd,1) -> 0.15 | D34: =Inputs!$B$39*IF($A34>=$F$8,1-lgd,1) -> 0.15 | E34: =Inputs!$B$39*IF($A34>=$F$9,1-lgd,1) -> 0.15 | F34: =Inputs!$B$39*IF($A34>=$F$10,1-lgd,1) -> 0.06 | G34: =Inputs!$B$39*IF($A34>=$F$11,1-lgd,1) -> 0.06 | H34: =Inputs!$B$39*IF($A34>=$F$12,1-lgd,1) -> 0.06 | I34: =Inputs!$B$39*IF($A34>=$F$13,1-lgd,1) -> 0.15 | J34: =Inputs!$B$39*IF($A34>=$F$14,1-lgd,1) -> 0.06 | K34: =Inputs!$B$39*IF($A34>=$F$15,1-lgd,1) -> 0.15 | L34: =SUM(B34:K34) -> 1.05 | M34: =MIN(L34,Inputs!$D$39) -> 0.1 | N34: =MIN(L34-M34,Inputs!$E$39) -> 0.1 | O34: =L34-M34-N34 -> 0.85 | P34: =Inputs!$C$39 -> 1.5
A35: 16 | B35: =Inputs!$B$40*IF($A35>=$F$6,1-lgd,1) -> 0.06 | C35: =Inputs!$B$40*IF($A35>=$F$7,1-lgd,1) -> 0.15 | D35: =Inputs!$B$40*IF($A35>=$F$8,1-lgd,1) -> 0.15 | E35: =Inputs!$B$40*IF($A35>=$F$9,1-lgd,1) -> 0.15 | F35: =Inputs!$B$40*IF($A35>=$F$10,1-lgd,1) -> 0.06 | G35: =Inputs!$B$40*IF($A35>=$F$11,1-lgd,1) -> 0.06 | H35: =Inputs!$B$40*IF($A35>=$F$12,1-lgd,1) -> 0.06 | I35: =Inputs!$B$40*IF($A35>=$F$13,1-lgd,1) -> 0.15 | J35: =Inputs!$B$40*IF($A35>=$F$14,1-lgd,1) -> 0.06 | K35: =Inputs!$B$40*IF($A35>=$F$15,1-lgd,1) -> 0.15 | L35: =SUM(B35:K35) -> 1.05 | M35: =MIN(L35,Inputs!$D$40) -> 0.1 | N35: =MIN(L35-M35,Inputs!$E$40) -> 0.1 | O35: =L35-M35-N35 -> 0.85 | P35: =Inputs!$C$40 -> 1.5
A36: 17 | B36: =Inputs!$B$41*IF($A36>=$F$6,1-lgd,1) -> 0.06 | C36: =Inputs!$B$41*IF($A36>=$F$7,1-lgd,1) -> 0.15 | D36: =Inputs!$B$41*IF($A36>=$F$8,1-lgd,1) -> 0.15 | E36: =Inputs!$B$41*IF($A36>=$F$9,1-lgd,1) -> 0.15 | F36: =Inputs!$B$41*IF($A36>=$F$10,1-lgd,1) -> 0.06 | G36: =Inputs!$B$41*IF($A36>=$F$11,1-lgd,1) -> 0.06 | H36: =Inputs!$B$41*IF($A36>=$F$12,1-lgd,1) -> 0.06 | I36: =Inputs!$B$41*IF($A36>=$F$13,1-lgd,1) -> 0.15 | J36: =Inputs!$B$41*IF($A36>=$F$14,1-lgd,1) -> 0.06 | K36: =Inputs!$B$41*IF($A36>=$F$15,1-lgd,1) -> 0.15 | L36: =SUM(B36:K36) -> 1.05 | M36: =MIN(L36,Inputs!$D$41) -> 0.1 | N36: =MIN(L36-M36,Inputs!$E$41) -> 0.1 | O36: =L36-M36-N36 -> 0.85 | P36: =Inputs!$C$41 -> 1.5
A37: 18 | B37: =Inputs!$B$42*IF($A37>=$F$6,1-lgd,1) -> 0.06 | C37: =Inputs!$B$42*IF($A37>=$F$7,1-lgd,1) -> 0.15 | D37: =Inputs!$B$42*IF($A37>=$F$8,1-lgd,1) -> 0.15 | E37: =Inputs!$B$42*IF($A37>=$F$9,1-lgd,1) -> 0.06 | F37: =Inputs!$B$42*IF($A37>=$F$10,1-lgd,1) -> 0.06 | G37: =Inputs!$B$42*IF($A37>=$F$11,1-lgd,1) -> 0.06 | H37: =Inputs!$B$42*IF($A37>=$F$12,1-lgd,1) -> 0.06 | I37: =Inputs!$B$42*IF($A37>=$F$13,1-lgd,1) -> 0.15 | J37: =Inputs!$B$42*IF($A37>=$F$14,1-lgd,1) -> 0.06 | K37: =Inputs!$B$42*IF($A37>=$F$15,1-lgd,1) -> 0.15 | L37: =SUM(B37:K37) -> 0.96 | M37: =MIN(L37,Inputs!$D$42) -> 0.1 | N37: =MIN(L37-M37,Inputs!$E$42) -> 0.1 | O37: =L37-M37-N37 -> 0.76 | P37: =Inputs!$C$42 -> 1.5
A38: 19 | B38: =Inputs!$B$43*IF($A38>=$F$6,1-lgd,1) -> 0.06 | C38: =Inputs!$B$43*IF($A38>=$F$7,1-lgd,1) -> 0.15 | D38: =Inputs!$B$43*IF($A38>=$F$8,1-lgd,1) -> 0.15 | E38: =Inputs!$B$43*IF($A38>=$F$9,1-lgd,1) -> 0.06 | F38: =Inputs!$B$43*IF($A38>=$F$10,1-lgd,1) -> 0.06 | G38: =Inputs!$B$43*IF($A38>=$F$11,1-lgd,1) -> 0.06 | H38: =Inputs!$B$43*IF($A38>=$F$12,1-lgd,1) -> 0.06 | I38: =Inputs!$B$43*IF($A38>=$F$13,1-lgd,1) -> 0.15 | J38: =Inputs!$B$43*IF($A38>=$F$14,1-lgd,1) -> 0.06 | K38: =Inputs!$B$43*IF($A38>=$F$15,1-lgd,1) -> 0.15 | L38: =SUM(B38:K38) -> 0.96 | M38: =MIN(L38,Inputs!$D$43) -> 0.1 | N38: =MIN(L38-M38,Inputs!$E$43) -> 0.1 | O38: =L38-M38-N38 -> 0.76 | P38: =Inputs!$C$43 -> 1.5
A39: 20 | B39: =Inputs!$B$44*IF($A39>=$F$6,1-lgd,1) -> 4.06 | C39: =Inputs!$B$44*IF($A39>=$F$7,1-lgd,1) -> 10.15 | D39: =Inputs!$B$44*IF($A39>=$F$8,1-lgd,1) -> 10.15 | E39: =Inputs!$B$44*IF($A39>=$F$9,1-lgd,1) -> 4.06 | F39: =Inputs!$B$44*IF($A39>=$F$10,1-lgd,1) -> 4.06 | G39: =Inputs!$B$44*IF($A39>=$F$11,1-lgd,1) -> 4.06 | H39: =Inputs!$B$44*IF($A39>=$F$12,1-lgd,1) -> 4.06 | I39: =Inputs!$B$44*IF($A39>=$F$13,1-lgd,1) -> 10.15 | J39: =Inputs!$B$44*IF($A39>=$F$14,1-lgd,1) -> 4.06 | K39: =Inputs!$B$44*IF($A39>=$F$15,1-lgd,1) -> 10.15 | L39: =SUM(B39:K39) -> 64.96 | M39: =MIN(L39,Inputs!$D$44) -> 20.1 | N39: =MIN(L39-M39,Inputs!$E$44) -> 10.1 | O39: =L39-M39-N39 -> 34.76 | P39: =Inputs!$C$44 -> 101.5
A40: Total | B40: =SUM(B20:B39) -> 5.47 | C40: =SUM(C20:C39) -> 13 | D40: =SUM(D20:D39) -> 13 | E40: =SUM(E20:E39) -> 6.73 | F40: =SUM(F20:F39) -> 5.47 | G40: =SUM(G20:G39) -> 6.19 | H40: =SUM(H20:H39) -> 6.01 | I40: =SUM(I20:I39) -> 13 | ... P40: =SUM(P20:P39) -> 130
A42: Check: pool total for this case on the CashFlows sheet minus the total above (should be 0) | L42: =ROUND(INDEX(CashFlows!$CH$18:$CH$1017,case_number)-L40,9) -> 0

Sheet Random
A1: Fixed random numbers
A2: 1000 cases x 10 bonds of independent standard normals, generated once in Python (numpy default_rng, seed 6103) and stored as values, so every recalculation uses the same numbers.
A17: Case | B17: Bond 1 | C17: Bond 2 | D17: Bond 3 | E17: Bond 4 | F17: Bond 5 | G17: Bond 6 | H17: Bond 7 | I17: Bond 8 | J17: Bond 9 | K17: Bond 10
A18: 1 | B18: -0.38920512 | C18: 1.1578214 | D18: 0.094403827 | E18: 0.34719004 | F18: 1.1101905 | G18: 0.65847745 | H18: 1.0467667 | I18: -0.47334846 | J18: -0.65241813 | K18: -0.11150449
A19: 2 | B19: -0.74367182 | C19: 1.2128351 | D19: -0.52110702 | E19: 0.86518459 | F19: 0.49348088 | G19: 0.54080648 | H19: 0.11461121 | I19: 0.80470891 | J19: 0.65395696 | K19: 0.21914285
A20: 3 | B20: 1.0929463 | C20: -1.0385714 | D20: 0.38965042 | E20: -0.49165919 | F20: -0.70360164 | G20: -0.18083038 | H20: -0.79099469 | I20: 0.12244058 | J20: -0.21931383 | K20: -0.47094783
A21: 4 | B21: -0.43419587 | C21: 1.9155 | D21: -0.9390708 | E21: -0.40533839 | F21: -0.050325829 | G21: 1.3117309 | H21: -0.8812356 | I21: -1.6061502 | J21: -0.91029713 | K21: -1.0652618
A22: 5 | B22: -1.8599871 | C22: 0.75061757 | D22: 0.2224588 | E22: -0.78341897 | F22: -1.5263177 | G22: -0.78531154 | H22: -0.83463465 | I22: -0.079703706 | J22: -0.83237702 | K22: 0.28584576
A23: 6 | B23: -0.98899926 | C23: 0.84004433 | D23: -0.01239904 | E23: -0.22507499 | F23: -0.527264 | G23: 1.5757522 | H23: 2.1505611 | I23: -1.1115642 | J23: -0.28865514 | K23: -1.1891091
A24: 7 | B24: 0.1824142 | C24: 2.5256254 | D24: 2.4366612 | E24: 0.065815591 | F24: 0.04363933 | G24: -0.97949866 | H24: -1.165684 | I24: 0.27741593 | J24: 0.57217075 | K24: 0.63146098
A25: 8 | B25: 0.0012540824 | C25: 0.54616113 | D25: -1.2245455 | E25: -0.87999384 | F25: -0.6068162 | G25: 1.4799411 | H25: -0.36687766 | I25: -0.40923304 | J25: 0.83344716 | K25: -0.51006943
A26: 9 | B26: -0.17451781 | C26: -0.9252292 | D26: 1.0322113 | E26: -0.24317831 | F26: 0.64296192 | G26: -0.084316859 | H26: -0.4738307 | I26: -0.16114309 | J26: -1.256032 | K26: 1.5574843
A27: 10 | B27: 1.2427491 | C27: -1.2554048 | D27: 1.0855786 | E27: -0.9129 | F27: 0.026784291 | G27: 1.6927249 | H27: 1.8710602 | I27: 0.20541021 | J27: 1.0689602 | K27: 0.63146848
A28: 11 | B28: -0.36636517 | C28: 0.63780897 | D28: 0.8268662 | E28: -0.27723605 | F28: 1.0565535 | G28: 2.2067925 | H28: -0.63085567 | I28: 0.30583377 | J28: -0.90104999 | K28: 0.1716398
A29: 12 | B29: 0.99133786 | C29: 0.52432613 | D29: -0.57589875 | E29: -0.20999668 | F29: 1.550588 | G29: 1.2715391 | H29: 0.030732581 | I29: -1.014409 | J29: -0.49343134 | K29: -2.088819
... A1017: 1000 | B1017: 0.39926353 | C1017: -0.3266436 | D1017: 2.2687587 | E1017: 0.5367822 | F1017: 1.431834 | G1017: -1.6368896 | H1017: 0.67420774 | I1017: -1.0191729 | J1017: 0.6192838 | K1017: 0.32254801

Sheet Defaults
A1: Correlated default times
A2: Cholesky factor L of the 10 x 10 matrix with 1 on the diagonal and rho elsewhere. Each case: x = L z, u = N(x), t = ln(1 - u) / ln(1 - pi) in years, default quarter = roundup(4 t); 21 means no default.
A3: L | B3: col 1 | C3: col 2 | D3: col 3 | E3: col 4 | F3: col 5 | G3: col 6 | H3: col 7 | I3: col 8 | J3: col 9 | K3: col 10
A4: Bond 1 | B4: 1 | C4: 0 | D4: 0 | E4: 0 | F4: 0 | G4: 0 | H4: 0 | I4: 0 | J4: 0 | K4: 0
A5: Bond 2 | B5: =rho/$B$4 -> 0.2 | C5: =SQRT(1-SUMSQ($B5:B5)) -> 0.9797959 | D5: 0 | E5: 0 | F5: 0 | G5: 0 | H5: 0 | I5: 0 | J5: 0 | K5: 0
A6: Bond 3 | B6: =rho/$B$4 -> 0.2 | C6: =(rho-SUMPRODUCT($B6:B6,$B5:B5))/C5 -> 0.16329932 | D6: =SQRT(1-SUMSQ($B6:C6)) -> 0.96609178 | E6: 0 | F6: 0 | G6: 0 | H6: 0 | I6: 0 | J6: 0 | K6: 0
A7: Bond 4 | B7: =rho/$B$4 -> 0.2 | C7: =(rho-SUMPRODUCT($B7:B7,$B5:B5))/C5 -> 0.16329932 | D7: =(rho-SUMPRODUCT($B7:C7,$B6:C6))/D6 -> 0.13801311 | E7: =SQRT(1-SUMSQ($B7:D7)) -> 0.95618289 | F7: 0 | G7: 0 | H7: 0 | I7: 0 | J7: 0 | K7: 0
A8: Bond 5 | B8: =rho/$B$4 -> 0.2 | C8: =(rho-SUMPRODUCT($B8:B8,$B5:B5))/C5 -> 0.16329932 | D8: =(rho-SUMPRODUCT($B8:C8,$B6:C6))/D6 -> 0.13801311 | E8: =(rho-SUMPRODUCT($B8:D8,$B7:D7))/E7 -> 0.11952286 | F8: =SQRT(1-SUMSQ($B8:E8)) -> 0.9486833 | G8: 0 | H8: 0 | I8: 0 | J8: 0 | K8: 0
A9: Bond 6 | B9: =rho/$B$4 -> 0.2 | C9: =(rho-SUMPRODUCT($B9:B9,$B5:B5))/C5 -> 0.16329932 | D9: =(rho-SUMPRODUCT($B9:C9,$B6:C6))/D6 -> 0.13801311 | E9: =(rho-SUMPRODUCT($B9:D9,$B7:D7))/E7 -> 0.11952286 | F9: =(rho-SUMPRODUCT($B9:E9,$B8:E8))/F8 -> 0.10540926 | G9: =SQRT(1-SUMSQ($B9:F9)) -> 0.94280904 | H9: 0 | I9: 0 | J9: 0 | K9: 0
A10: Bond 7 | B10: =rho/$B$4 -> 0.2 | C10: =(rho-SUMPRODUCT($B10:B10,$B5:B5))/C5 -> 0.16329932 | D10: =(rho-SUMPRODUCT($B10:C10,$B6:C6))/D6 -> 0.13801311 | E10: =(rho-SUMPRODUCT($B10:D10,$B7:D7))/E7 -> 0.11952286 | F10: =(rho-SUMPRODUCT($B10:E10,$B8:E8))/F8 -> 0.10540926 | G10: =(rho-SUMPRODUCT($B10:F10,$B9:F9))/G9 -> 0.094280904 | H10: =SQRT(1-SUMSQ($B10:G10)) -> 0.93808315 | I10: 0 | J10: 0 | K10: 0
A11: Bond 8 | B11: =rho/$B$4 -> 0.2 | C11: =(rho-SUMPRODUCT($B11:B11,$B5:B5))/C5 -> 0.16329932 | D11: =(rho-SUMPRODUCT($B11:C11,$B6:C6))/D6 -> 0.13801311 | E11: =(rho-SUMPRODUCT($B11:D11,$B7:D7))/E7 -> 0.11952286 | F11: =(rho-SUMPRODUCT($B11:E11,$B8:E8))/F8 -> 0.10540926 | G11: =(rho-SUMPRODUCT($B11:F11,$B9:F9))/G9 -> 0.094280904 | H11: =(rho-SUMPRODUCT($B11:G11,$B10:G10))/H10 -> 0.085280287 | I11: =SQRT(1-SUMSQ($B11:H11)) -> 0.93419873 | J11: 0 | K11: 0
A12: Bond 9 | B12: =rho/$B$4 -> 0.2 | C12: =(rho-SUMPRODUCT($B12:B12,$B5:B5))/C5 -> 0.16329932 | D12: =(rho-SUMPRODUCT($B12:C12,$B6:C6))/D6 -> 0.13801311 | E12: =(rho-SUMPRODUCT($B12:D12,$B7:D7))/E7 -> 0.11952286 | F12: =(rho-SUMPRODUCT($B12:E12,$B8:E8))/F8 -> 0.10540926 | G12: =(rho-SUMPRODUCT($B12:F12,$B9:F9))/G9 -> 0.094280904 | H12: =(rho-SUMPRODUCT($B12:G12,$B10:G10))/H10 -> 0.085280287 | I12: =(rho-SUMPRODUCT($B12:H12,$B11:H11))/I11 -> 0.077849894 | J12: =SQRT(1-SUMSQ($B12:I12)) -> 0.93094934 | K12: 0
A13: Bond 10 | B13: =rho/$B$4 -> 0.2 | C13: =(rho-SUMPRODUCT($B13:B13,$B5:B5))/C5 -> 0.16329932 | D13: =(rho-SUMPRODUCT($B13:C13,$B6:C6))/D6 -> 0.13801311 | E13: =(rho-SUMPRODUCT($B13:D13,$B7:D7))/E7 -> 0.11952286 | F13: =(rho-SUMPRODUCT($B13:E13,$B8:E8))/F8 -> 0.10540926 | G13: =(rho-SUMPRODUCT($B13:F13,$B9:F9))/G9 -> 0.094280904 | H13: =(rho-SUMPRODUCT($B13:G13,$B10:G10))/H10 -> 0.085280287 | I13: =(rho-SUMPRODUCT($B13:H13,$B11:H11))/I11 -> 0.077849894 | J13: =(rho-SUMPRODUCT($B13:I13,$B12:I12))/J12 -> 0.071611487 | K13: =SQRT(1-SUMSQ($B13:J13)) -> 0.92819096
B16: Correlated normal x | M16: Uniform u = N(x) | X16: Default time t (years) | AI16: Default quarter (21 = none)
A17: Case | B17: Bond 1 | C17: Bond 2 | D17: Bond 3 | E17: Bond 4 | F17: Bond 5 | G17: Bond 6 | H17: Bond 7 | I17: Bond 8 | J17: Bond 9 | K17: Bond 10 | M17: Bond 1 | N17: Bond 2 | O17: Bond 3 | P17: Bond 4 | Q17: Bond 5 | R17: Bond 6 | S17: Bond 7 | T17: Bond 8 | U17: Bond 9 | V17: Bond 10 | X17: Bond 1 | Y17: Bond 2 | Z17: Bond 3 | AA17: Bond 4 | AB17: Bond 5 | AC17: Bond 6 | AD17: Bond 7 | AE17: Bond 8 | AF17: Bond 9 | AG17: Bond 10 | AI17: Bond 1 | AJ17: Bond 2 | AK17: Bond 3 | AL17: Bond 4 | AM17: Bond 5 | AN17: Bond 6 | AO17: Bond 7 | AP17: Bond 8 | AQ17: Bond 9 | AR17: Bond 10 | AT17: Defaults in 5 years
A18: 1 | B18: =SUMPRODUCT(Random!$B18:$K18,$B$4:$K$4) -> -0.38920512 | C18: =SUMPRODUCT(Random!$B18:$K18,$B$5:$K$5) -> 1.0565876 | D18: =SUMPRODUCT(Random!$B18:$K18,$B$6:$K$6) -> 0.20243318 | E18: =SUMPRODUCT(Random!$B18:$K18,$B$7:$K$7) -> 0.45623656 | F18: =SUMPRODUCT(Random!$B18:$K18,$B$8:$K$8) -> 1.2189757 | G18: =SUMPRODUCT(Random!$B18:$K18,$B$9:$K$9) -> 0.90359938 | H18: =SUMPRODUCT(Random!$B18:$K18,$B$10:$K$10) -> 1.326817 | I18: =SUMPRODUCT(Random!$B18:$K18,$B$11:$K$11) -> -0.0080702337 | J18: =SUMPRODUCT(Random!$B18:$K18,$B$12:$K$12) -> -0.21008705 | K18: =SUMPRODUCT(Random!$B18:$K18,$B$13:$K$13) -> 0.24706308 | M18: =NORMSDIST(B18) -> 0.34856221 | N18: =NORMSDIST(C18) -> 0.85465009 | O18: =NORMSDIST(D18) -> 0.58021096 | P18: =NORMSDIST(E18) -> 0.67589006 | Q18: =NORMSDIST(F18) -> 0.8885733 | R18: =NORMSDIST(G18) -> 0.81689606 | S18: =NORMSDIST(H18) -> 0.90771538 | T18: =NORMSDIST(I18) -> 0.49678048 | ... V18: =NORMSDIST(K18) -> 0.5975703 | X18: =IF(pd_annual=0,"never",LN(1-M18)/LN(1-pd_annual)) -> 10.49859 | Y18: =IF(pd_annual=0,"never",LN(1-N18)/LN(1-pd_annual)) -> 47.244415 | Z18: =IF(pd_annual=0,"never",LN(1-O18)/LN(1-pd_annual)) -> 21.26312 | AA18: =IF(pd_annual=0,"never",LN(1-P18)/LN(1-pd_annual)) -> 27.599644 | AB18: =IF(pd_annual=0,"never",LN(1-Q18)/LN(1-pd_annual)) -> 53.755048 | AC18: =IF(pd_annual=0,"never",LN(1-R18)/LN(1-pd_annual)) -> 41.587908 | AD18: =IF(pd_annual=0,"never",LN(1-S18)/LN(1-pd_annual)) -> 58.3724 | AE18: =IF(pd_annual=0,"never",LN(1-T18)/LN(1-pd_annual)) -> 16.822519 | ... AG18: =IF(pd_annual=0,"never",LN(1-V18)/LN(1-pd_annual)) -> 22.297657 | AI18: =IF(pd_annual=0,21,MIN(21,MAX(1,ROUNDUP(4*X18,0)))) -> 21 | AJ18: =IF(pd_annual=0,21,MIN(21,MAX(1,ROUNDUP(4*Y18,0)))) -> 21 | AK18: =IF(pd_annual=0,21,MIN(21,MAX(1,ROUNDUP(4*Z18,0)))) -> 21 | AL18: =IF(pd_annual=0,21,MIN(21,MAX(1,ROUNDUP(4*AA18,0)))) -> 21 | AM18: =IF(pd_annual=0,21,MIN(21,MAX(1,ROUNDUP(4*AB18,0)))) -> 21 | AN18: =IF(pd_annual=0,21,MIN(21,MAX(1,ROUNDUP(4*AC18,0)))) -> 21 | AO18: =IF(pd_annual=0,21,MIN(21,MAX(1,ROUNDUP(4*AD18,0)))) -> 21 | AP18: =IF(pd_annual=0,21,MIN(21,MAX(1,ROUNDUP(4*AE18,0)))) -> 21 | ... AR18: =IF(pd_annual=0,21,MIN(21,MAX(1,ROUNDUP(4*AG18,0)))) -> 21 | AT18: =COUNTIF($AI18:$AR18,"<=20") -> 0
A19: 2 | B19: =SUMPRODUCT(Random!$B19:$K19,$B$4:$K$4) -> -0.74367182 | C19: =SUMPRODUCT(Random!$B19:$K19,$B$5:$K$5) -> 1.0395965 | D19: =SUMPRODUCT(Random!$B19:$K19,$B$6:$K$6) -> -0.45411642 | E19: =SUMPRODUCT(Random!$B19:$K19,$B$7:$K$7) -> 0.80467588 | F19: =SUMPRODUCT(Random!$B19:$K19,$B$8:$K$8) -> 0.54896759 | G19: =SUMPRODUCT(Random!$B19:$K19,$B$9:$K$9) -> 0.64270521 | H19: =SUMPRODUCT(Random!$B19:$K19,$B$10:$K$10) -> 0.29133055 | I19: =SUMPRODUCT(Random!$B19:$K19,$B$11:$K$11) -> 0.94534782 | J19: =SUMPRODUCT(Random!$B19:$K19,$B$12:$K$12) -> 0.86503707 | K19: =SUMPRODUCT(Random!$B19:$K19,$B$13:$K$13) -> 0.50647352 | M19: =NORMSDIST(B19) -> 0.22853752 | N19: =NORMSDIST(C19) -> 0.85073631 | O19: =NORMSDIST(D19) -> 0.32487252 | P19: =NORMSDIST(E19) -> 0.78949663 | Q19: =NORMSDIST(F19) -> 0.70848615 | R19: =NORMSDIST(G19) -> 0.7397923 | S19: =NORMSDIST(H19) -> 0.61460074 | T19: =NORMSDIST(I19) -> 0.82775933 | ... V19: =NORMSDIST(K19) -> 0.69373786 | X19: =IF(pd_annual=0,"never",LN(1-M19)/LN(1-pd_annual)) -> 6.3560647 | Y19: =IF(pd_annual=0,"never",LN(1-N19)/LN(1-pd_annual)) -> 46.593529 | Z19: =IF(pd_annual=0,"never",LN(1-O19)/LN(1-pd_annual)) -> 9.6235803 | AA19: =IF(pd_annual=0,"never",LN(1-P19)/LN(1-pd_annual)) -> 38.171913 | AB19: =IF(pd_annual=0,"never",LN(1-Q19)/LN(1-pd_annual)) -> 30.196167 | AC19: =IF(pd_annual=0,"never",LN(1-R19)/LN(1-pd_annual)) -> 32.979161 | AD19: =IF(pd_annual=0,"never",LN(1-S19)/LN(1-pd_annual)) -> 23.356905 | AE19: =IF(pd_annual=0,"never",LN(1-T19)/LN(1-pd_annual)) -> 43.086149 | ... AG19: =IF(pd_annual=0,"never",LN(1-V19)/LN(1-pd_annual)) -> 28.987165 | AI19: =IF(pd_annual=0,21,MIN(21,MAX(1,ROUNDUP(4*X19,0)))) -> 21 | AJ19: =IF(pd_annual=0,21,MIN(21,MAX(1,ROUNDUP(4*Y19,0)))) -> 21 | AK19: =IF(pd_annual=0,21,MIN(21,MAX(1,ROUNDUP(4*Z19,0)))) -> 21 | AL19: =IF(pd_annual=0,21,MIN(21,MAX(1,ROUNDUP(4*AA19,0)))) -> 21 | AM19: =IF(pd_annual=0,21,MIN(21,MAX(1,ROUNDUP(4*AB19,0)))) -> 21 | AN19: =IF(pd_annual=0,21,MIN(21,MAX(1,ROUNDUP(4*AC19,0)))) -> 21 | AO19: =IF(pd_annual=0,21,MIN(21,MAX(1,ROUNDUP(4*AD19,0)))) -> 21 | AP19: =IF(pd_annual=0,21,MIN(21,MAX(1,ROUNDUP(4*AE19,0)))) -> 21 | ... AR19: =IF(pd_annual=0,21,MIN(21,MAX(1,ROUNDUP(4*AG19,0)))) -> 21 | AT19: =COUNTIF($AI19:$AR19,"<=20") -> 0
A20: 3 | B20: =SUMPRODUCT(Random!$B20:$K20,$B$4:$K$4) -> 1.0929463 | C20: =SUMPRODUCT(Random!$B20:$K20,$B$5:$K$5) -> -0.79899878 | D20: =SUMPRODUCT(Random!$B20:$K20,$B$6:$K$6) -> 0.42542933 | E20: =SUMPRODUCT(Random!$B20:$K20,$B$7:$K$7) -> -0.36734798 | F20: =SUMPRODUCT(Random!$B20:$K20,$B$8:$K$8) -> -0.62349151 | G20: =SUMPRODUCT(Random!$B20:$K20,$B$9:$K$9) -> -0.20065103 | H20: =SUMPRODUCT(Random!$B20:$K20,$B$10:$K$10) -> -0.78923015 | I20: =SUMPRODUCT(Random!$B20:$K20,$B$11:$K$11) -> -0.00028378441 | J20: =SUMPRODUCT(Random!$B20:$K20,$B$12:$K$12) -> -0.30930569 | K20: =SUMPRODUCT(Random!$B20:$K20,$B$13:$K$13) -> -0.55797054 | M20: =NORMSDIST(B20) -> 0.86279132 | N20: =NORMSDIST(C20) -> 0.21214556 | O20: =NORMSDIST(D20) -> 0.66473814 | P20: =NORMSDIST(E20) -> 0.35667974 | Q20: =NORMSDIST(F20) -> 0.26648079 | R20: =NORMSDIST(G20) -> 0.42048573 | S20: =NORMSDIST(H20) -> 0.21498875 | T20: =NORMSDIST(I20) -> 0.49988679 | ... V20: =NORMSDIST(K20) -> 0.28843225 | X20: =IF(pd_annual=0,"never",LN(1-M20)/LN(1-pd_annual)) -> 48.656425 | Y20: =IF(pd_annual=0,"never",LN(1-N20)/LN(1-pd_annual)) -> 5.8410161 | Z20: =IF(pd_annual=0,"never",LN(1-O20)/LN(1-pd_annual)) -> 26.770945 | AA20: =IF(pd_annual=0,"never",LN(1-P20)/LN(1-pd_annual)) -> 10.805758 | AB20: =IF(pd_annual=0,"never",LN(1-Q20)/LN(1-pd_annual)) -> 7.5915324 | AC20: =IF(pd_annual=0,"never",LN(1-R20)/LN(1-pd_annual)) -> 13.364486 | AD20: =IF(pd_annual=0,"never",LN(1-S20)/LN(1-pd_annual)) -> 5.9295787 | AE20: =IF(pd_annual=0,"never",LN(1-T20)/LN(1-pd_annual)) -> 16.974202 | ... AG20: =IF(pd_annual=0,"never",LN(1-V20)/LN(1-pd_annual)) -> 8.3358162 | AI20: =IF(pd_annual=0,21,MIN(21,MAX(1,ROUNDUP(4*X20,0)))) -> 21 | AJ20: =IF(pd_annual=0,21,MIN(21,MAX(1,ROUNDUP(4*Y20,0)))) -> 21 | AK20: =IF(pd_annual=0,21,MIN(21,MAX(1,ROUNDUP(4*Z20,0)))) -> 21 | AL20: =IF(pd_annual=0,21,MIN(21,MAX(1,ROUNDUP(4*AA20,0)))) -> 21 | AM20: =IF(pd_annual=0,21,MIN(21,MAX(1,ROUNDUP(4*AB20,0)))) -> 21 | AN20: =IF(pd_annual=0,21,MIN(21,MAX(1,ROUNDUP(4*AC20,0)))) -> 21 | AO20: =IF(pd_annual=0,21,MIN(21,MAX(1,ROUNDUP(4*AD20,0)))) -> 21 | AP20: =IF(pd_annual=0,21,MIN(21,MAX(1,ROUNDUP(4*AE20,0)))) -> 21 | ... AR20: =IF(pd_annual=0,21,MIN(21,MAX(1,ROUNDUP(4*AG20,0)))) -> 21 | AT20: =COUNTIF($AI20:$AR20,"<=20") -> 0
A21: 4 | B21: =SUMPRODUCT(Random!$B21:$K21,$B$4:$K$4) -> -0.43419587 | C21: =SUMPRODUCT(Random!$B21:$K21,$B$5:$K$5) -> 1.7899599 | D21: =SUMPRODUCT(Random!$B21:$K21,$B$6:$K$6) -> -0.68126791 | E21: =SUMPRODUCT(Random!$B21:$K21,$B$7:$K$7) -> -0.29122104 | F21: =SUMPRODUCT(Random!$B21:$K21,$B$8:$K$8) -> 0.00016611268 | G21: =SUMPRODUCT(Random!$B21:$K21,$B$9:$K$9) -> 1.2793163 | H21: =SUMPRODUCT(Random!$B21:$K21,$B$10:$K$10) -> -0.66039652 | I21: =SUMPRODUCT(Random!$B21:$K21,$B$11:$K$11) -> -1.4093398 | J21: =SUMPRODUCT(Random!$B21:$K21,$B$12:$K$12) -> -0.88135541 | K21: =SUMPRODUCT(Random!$B21:$K21,$B$13:$K$13) -> -1.087869 | M21: =NORMSDIST(B21) -> 0.3320731 | N21: =NORMSDIST(C21) -> 0.96326982 | O21: =NORMSDIST(D21) -> 0.24785099 | P21: =NORMSDIST(E21) -> 0.38544114 | Q21: =NORMSDIST(F21) -> 0.50006627 | R21: =NORMSDIST(G21) -> 0.89960715 | S21: =NORMSDIST(H21) -> 0.2544997 | T21: =NORMSDIST(I21) -> 0.079367358 | ... V21: =NORMSDIST(K21) -> 0.13832648 | X21: =IF(pd_annual=0,"never",LN(1-M21)/LN(1-pd_annual)) -> 9.8862526 | Y21: =IF(pd_annual=0,"never",LN(1-N21)/LN(1-pd_annual)) -> 80.940596 | Z21: =IF(pd_annual=0,"never",LN(1-O21)/LN(1-pd_annual)) -> 6.9771414 | AA21: =IF(pd_annual=0,"never",LN(1-P21)/LN(1-pd_annual)) -> 11.926183 | AB21: =IF(pd_annual=0,"never",LN(1-Q21)/LN(1-pd_annual)) -> 16.982995 | AC21: =IF(pd_annual=0,"never",LN(1-R21)/LN(1-pd_annual)) -> 56.309456 | AD21: =IF(pd_annual=0,"never",LN(1-S21)/LN(1-pd_annual)) -> 7.1946447 | AE21: =IF(pd_annual=0,"never",LN(1-T21)/LN(1-pd_annual)) -> 2.0257264 | ... AG21: =IF(pd_annual=0,"never",LN(1-V21)/LN(1-pd_annual)) -> 3.6470248 | AI21: =IF(pd_annual=0,21,MIN(21,MAX(1,ROUNDUP(4*X21,0)))) -> 21 | AJ21: =IF(pd_annual=0,21,MIN(21,MAX(1,ROUNDUP(4*Y21,0)))) -> 21 | AK21: =IF(pd_annual=0,21,MIN(21,MAX(1,ROUNDUP(4*Z21,0)))) -> 21 | AL21: =IF(pd_annual=0,21,MIN(21,MAX(1,ROUNDUP(4*AA21,0)))) -> 21 | AM21: =IF(pd_annual=0,21,MIN(21,MAX(1,ROUNDUP(4*AB21,0)))) -> 21 | AN21: =IF(pd_annual=0,21,MIN(21,MAX(1,ROUNDUP(4*AC21,0)))) -> 21 | AO21: =IF(pd_annual=0,21,MIN(21,MAX(1,ROUNDUP(4*AD21,0)))) -> 21 | AP21: =IF(pd_annual=0,21,MIN(21,MAX(1,ROUNDUP(4*AE21,0)))) -> 9 | ... AR21: =IF(pd_annual=0,21,MIN(21,MAX(1,ROUNDUP(4*AG21,0)))) -> 15 | AT21: =COUNTIF($AI21:$AR21,"<=20") -> 2
A22: 5 | B22: =SUMPRODUCT(Random!$B22:$K22,$B$4:$K$4) -> -1.8599871 | C22: =SUMPRODUCT(Random!$B22:$K22,$B$5:$K$5) -> 0.36345459 | D22: =SUMPRODUCT(Random!$B22:$K22,$B$6:$K$6) -> -0.034506468 | E22: =SUMPRODUCT(Random!$B22:$K22,$B$7:$K$7) -> -0.96781167 | F22: =SUMPRODUCT(Random!$B22:$K22,$B$8:$K$8) -> -1.7603485 | G22: =SUMPRODUCT(Random!$B22:$K22,$B$9:$K$9) -> -1.2136432 | H22: =SUMPRODUCT(Random!$B22:$K22,$B$10:$K$10) -> -1.3302409 | I22: =SUMPRODUCT(Random!$B22:$K22,$B$11:$K$11) -> -0.69292121 | J22: =SUMPRODUCT(Random!$B22:$K22,$B$12:$K$12) -> -1.3995679 | K22: =SUMPRODUCT(Random!$B22:$K22,$B$13:$K$13) -> -0.41895534 | M22: =NORMSDIST(B22) -> 0.031443676 | N22: =NORMSDIST(C22) -> 0.64186734 | O22: =NORMSDIST(D22) -> 0.48623664 | P22: =NORMSDIST(E22) -> 0.16656922 | Q22: =NORMSDIST(F22) -> 0.039174371 | R22: =NORMSDIST(G22) -> 0.11244201 | S22: =NORMSDIST(H22) -> 0.091719452 | T22: =NORMSDIST(I22) -> 0.2441795 | ... V22: =NORMSDIST(K22) -> 0.33762439 | X22: =IF(pd_annual=0,"never",LN(1-M22)/LN(1-pd_annual)) -> 0.78263304 | Y22: =IF(pd_annual=0,"never",LN(1-N22)/LN(1-pd_annual)) -> 25.154376 | Z22: =IF(pd_annual=0,"never",LN(1-O22)/LN(1-pd_annual)) -> 16.314551 | AA22: =IF(pd_annual=0,"never",LN(1-P22)/LN(1-pd_annual)) -> 4.4633935 | AB22: =IF(pd_annual=0,"never",LN(1-Q22)/LN(1-pd_annual)) -> 0.97894124 | AC22: =IF(pd_annual=0,"never",LN(1-R22)/LN(1-pd_annual)) -> 2.921989 | AD22: =IF(pd_annual=0,"never",LN(1-S22)/LN(1-pd_annual)) -> 2.3566211 | AE22: =IF(pd_annual=0,"never",LN(1-T22)/LN(1-pd_annual)) -> 6.8578561 | ... AG22: =IF(pd_annual=0,"never",LN(1-V22)/LN(1-pd_annual)) -> 10.0907 | AI22: =IF(pd_annual=0,21,MIN(21,MAX(1,ROUNDUP(4*X22,0)))) -> 4 | AJ22: =IF(pd_annual=0,21,MIN(21,MAX(1,ROUNDUP(4*Y22,0)))) -> 21 | AK22: =IF(pd_annual=0,21,MIN(21,MAX(1,ROUNDUP(4*Z22,0)))) -> 21 | AL22: =IF(pd_annual=0,21,MIN(21,MAX(1,ROUNDUP(4*AA22,0)))) -> 18 | AM22: =IF(pd_annual=0,21,MIN(21,MAX(1,ROUNDUP(4*AB22,0)))) -> 4 | AN22: =IF(pd_annual=0,21,MIN(21,MAX(1,ROUNDUP(4*AC22,0)))) -> 12 | AO22: =IF(pd_annual=0,21,MIN(21,MAX(1,ROUNDUP(4*AD22,0)))) -> 10 | AP22: =IF(pd_annual=0,21,MIN(21,MAX(1,ROUNDUP(4*AE22,0)))) -> 21 | ... AR22: =IF(pd_annual=0,21,MIN(21,MAX(1,ROUNDUP(4*AG22,0)))) -> 21 | AT22: =COUNTIF($AI22:$AR22,"<=20") -> 6
A23: 6 | B23: =SUMPRODUCT(Random!$B23:$K23,$B$4:$K$4) -> -0.98899926 | C23: =SUMPRODUCT(Random!$B23:$K23,$B$5:$K$5) -> 0.62527213 | D23: =SUMPRODUCT(Random!$B23:$K23,$B$6:$K$6) -> -0.072599798 | E23: =SUMPRODUCT(Random!$B23:$K23,$B$7:$K$7) -> -0.27754527 | F23: =SUMPRODUCT(Random!$B23:$K23,$B$8:$K$8) -> -0.58944057 | G23: =SUMPRODUCT(Random!$B23:$K23,$B$9:$K$9) -> 1.3408209 | H23: =SUMPRODUCT(Random!$B23:$K23,$B$10:$K$10) -> 2.0211559 | I23: =SUMPRODUCT(Random!$B23:$K23,$B$11:$K$11) -> -0.85127058 | J23: =SUMPRODUCT(Random!$B23:$K23,$B$12:$K$12) -> -0.16810719 | K23: =SUMPRODUCT(Random!$B23:$K23,$B$13:$K$13) -> -1.0237753 | M23: =NORMSDIST(B23) -> 0.16133175 | N23: =NORMSDIST(C23) -> 0.73410377 | O23: =NORMSDIST(D23) -> 0.47106229 | P23: =NORMSDIST(E23) -> 0.39068073 | Q23: =NORMSDIST(F23) -> 0.27778288 | R23: =NORMSDIST(G23) -> 0.91001069 | S23: =NORMSDIST(H23) -> 0.97836819 | T23: =NORMSDIST(I23) -> 0.19730953 | ... V23: =NORMSDIST(K23) -> 0.15297072 | X23: =IF(pd_annual=0,"never",LN(1-M23)/LN(1-pd_annual)) -> 4.3099331 | Y23: =IF(pd_annual=0,"never",LN(1-N23)/LN(1-pd_annual)) -> 32.449398 | Z23: =IF(pd_annual=0,"never",LN(1-O23)/LN(1-pd_annual)) -> 15.601506 | AA23: =IF(pd_annual=0,"never",LN(1-P23)/LN(1-pd_annual)) -> 12.135931 | AB23: =IF(pd_annual=0,"never",LN(1-Q23)/LN(1-pd_annual)) -> 7.971915 | AC23: =IF(pd_annual=0,"never",LN(1-R23)/LN(1-pd_annual)) -> 58.989387 | AD23: =IF(pd_annual=0,"never",LN(1-S23)/LN(1-pd_annual)) -> 93.90992 | AE23: =IF(pd_annual=0,"never",LN(1-T23)/LN(1-pd_annual)) -> 5.384012 | ... AG23: =IF(pd_annual=0,"never",LN(1-V23)/LN(1-pd_annual)) -> 4.0669256 | AI23: =IF(pd_annual=0,21,MIN(21,MAX(1,ROUNDUP(4*X23,0)))) -> 18 | AJ23: =IF(pd_annual=0,21,MIN(21,MAX(1,ROUNDUP(4*Y23,0)))) -> 21 | AK23: =IF(pd_annual=0,21,MIN(21,MAX(1,ROUNDUP(4*Z23,0)))) -> 21 | AL23: =IF(pd_annual=0,21,MIN(21,MAX(1,ROUNDUP(4*AA23,0)))) -> 21 | AM23: =IF(pd_annual=0,21,MIN(21,MAX(1,ROUNDUP(4*AB23,0)))) -> 21 | AN23: =IF(pd_annual=0,21,MIN(21,MAX(1,ROUNDUP(4*AC23,0)))) -> 21 | AO23: =IF(pd_annual=0,21,MIN(21,MAX(1,ROUNDUP(4*AD23,0)))) -> 21 | AP23: =IF(pd_annual=0,21,MIN(21,MAX(1,ROUNDUP(4*AE23,0)))) -> 21 | ... AR23: =IF(pd_annual=0,21,MIN(21,MAX(1,ROUNDUP(4*AG23,0)))) -> 17 | AT23: =COUNTIF($AI23:$AR23,"<=20") -> 2
A24: 7 | B24: =SUMPRODUCT(Random!$B24:$K24,$B$4:$K$4) -> 0.1824142 | C24: =SUMPRODUCT(Random!$B24:$K24,$B$5:$K$5) -> 2.5110802 | D24: =SUMPRODUCT(Random!$B24:$K24,$B$6:$K$6) -> 2.8029541 | E24: =SUMPRODUCT(Random!$B24:$K24,$B$7:$K$7) -> 0.84813868 | F24: =SUMPRODUCT(Random!$B24:$K24,$B$8:$K$8) -> 0.83447331 | G24: =SUMPRODUCT(Random!$B24:$K24,$B$9:$K$9) -> -0.1258068 | H24: =SUMPRODUCT(Random!$B24:$K24,$B$10:$K$10) -> -0.38818314 | I24: =SUMPRODUCT(Random!$B24:$K24,$B$11:$K$11) -> 0.86507712 | J24: =SUMPRODUCT(Random!$B24:$K24,$B$12:$K$12) -> 1.1601743 | K24: =SUMPRODUCT(Random!$B24:$K24,$B$13:$K$13) -> 1.2546027 | M24: =NORMSDIST(B24) -> 0.57237116 | N24: =NORMSDIST(C24) -> 0.99398188 | O24: =NORMSDIST(D24) -> 0.99746816 | P24: =NORMSDIST(E24) -> 0.80181963 | Q24: =NORMSDIST(F24) -> 0.79799284 | R24: =NORMSDIST(G24) -> 0.44994243 | S24: =NORMSDIST(H24) -> 0.34894025 | T24: =NORMSDIST(I24) -> 0.80650177 | ... V24: =NORMSDIST(K24) -> 0.89518848 | X24: =IF(pd_annual=0,"never",LN(1-M24)/LN(1-pd_annual)) -> 20.809852 | Y24: =IF(pd_annual=0,"never",LN(1-N24)/LN(1-pd_annual)) -> 125.25064 | Z24: =IF(pd_annual=0,"never",LN(1-O24)/LN(1-pd_annual)) -> 146.46044 | AA24: =IF(pd_annual=0,"never",LN(1-P24)/LN(1-pd_annual)) -> 39.649647 | AB24: =IF(pd_annual=0,"never",LN(1-Q24)/LN(1-pd_annual)) -> 39.181136 | AC24: =IF(pd_annual=0,"never",LN(1-R24)/LN(1-pd_annual)) -> 14.642409 | AD24: =IF(pd_annual=0,"never",LN(1-S24)/LN(1-pd_annual)) -> 10.51281 | AE24: =IF(pd_annual=0,"never",LN(1-T24)/LN(1-pd_annual)) -> 40.235342 | ... AG24: =IF(pd_annual=0,"never",LN(1-V24)/LN(1-pd_annual)) -> 55.254322 | AI24: =IF(pd_annual=0,21,MIN(21,MAX(1,ROUNDUP(4*X24,0)))) -> 21 | AJ24: =IF(pd_annual=0,21,MIN(21,MAX(1,ROUNDUP(4*Y24,0)))) -> 21 | AK24: =IF(pd_annual=0,21,MIN(21,MAX(1,ROUNDUP(4*Z24,0)))) -> 21 | AL24: =IF(pd_annual=0,21,MIN(21,MAX(1,ROUNDUP(4*AA24,0)))) -> 21 | AM24: =IF(pd_annual=0,21,MIN(21,MAX(1,ROUNDUP(4*AB24,0)))) -> 21 | AN24: =IF(pd_annual=0,21,MIN(21,MAX(1,ROUNDUP(4*AC24,0)))) -> 21 | AO24: =IF(pd_annual=0,21,MIN(21,MAX(1,ROUNDUP(4*AD24,0)))) -> 21 | AP24: =IF(pd_annual=0,21,MIN(21,MAX(1,ROUNDUP(4*AE24,0)))) -> 21 | ... AR24: =IF(pd_annual=0,21,MIN(21,MAX(1,ROUNDUP(4*AG24,0)))) -> 21 | AT24: =COUNTIF($AI24:$AR24,"<=20") -> 0
A25: 8 | B25: =SUMPRODUCT(Random!$B25:$K25,$B$4:$K$4) -> 0.0012540824 | C25: =SUMPRODUCT(Random!$B25:$K25,$B$5:$K$5) -> 0.53537725 | D25: =SUMPRODUCT(Random!$B25:$K25,$B$6:$K$6) -> -1.0935848 | E25: =SUMPRODUCT(Random!$B25:$K25,$B$7:$K$7) -> -0.92099983 | F25: =SUMPRODUCT(Random!$B25:$K25,$B$8:$K$8) -> -0.76042056 | G25: =SUMPRODUCT(Random!$B25:$K25,$B$9:$K$9) -> 1.1465936 | H25: =SUMPRODUCT(Random!$B25:$K25,$B$10:$K$10) -> -0.45333978 | I25: =SUMPRODUCT(Random!$B25:$K25,$B$11:$K$11) -> -0.52277045 | J25: =SUMPRODUCT(Random!$B25:$K25,$B$12:$K$12) -> 0.60357287 | K25: =SUMPRODUCT(Random!$B25:$K25,$B$13:$K$13) -> -0.58608165 | M25: =NORMSDIST(B25) -> 0.50050031 | N25: =NORMSDIST(C25) -> 0.70380549 | O25: =NORMSDIST(D25) -> 0.13706855 | P25: =NORMSDIST(E25) -> 0.17852526 | Q25: =NORMSDIST(F25) -> 0.22350162 | R25: =NORMSDIST(G25) -> 0.87422519 | S25: =NORMSDIST(H25) -> 0.32515205 | T25: =NORMSDIST(I25) -> 0.300567 | ... V25: =NORMSDIST(K25) -> 0.27891032 | X25: =IF(pd_annual=0,"never",LN(1-M25)/LN(1-pd_annual)) -> 17.004272 | Y25: =IF(pd_annual=0,"never",LN(1-N25)/LN(1-pd_annual)) -> 29.805964 | Z25: =IF(pd_annual=0,"never",LN(1-O25)/LN(1-pd_annual)) -> 3.6112892 | AA25: =IF(pd_annual=0,"never",LN(1-P25)/LN(1-pd_annual)) -> 4.8173562 | AB25: =IF(pd_annual=0,"never",LN(1-Q25)/LN(1-pd_annual)) -> 6.1966772 | AC25: =IF(pd_annual=0,"never",LN(1-R25)/LN(1-pd_annual)) -> 50.787872 | AD25: =IF(pd_annual=0,"never",LN(1-S25)/LN(1-pd_annual)) -> 9.633725 | AE25: =IF(pd_annual=0,"never",LN(1-T25)/LN(1-pd_annual)) -> 8.7571732 | ... AG25: =IF(pd_annual=0,"never",LN(1-V25)/LN(1-pd_annual)) -> 8.0101861 | AI25: =IF(pd_annual=0,21,MIN(21,MAX(1,ROUNDUP(4*X25,0)))) -> 21 | AJ25: =IF(pd_annual=0,21,MIN(21,MAX(1,ROUNDUP(4*Y25,0)))) -> 21 | AK25: =IF(pd_annual=0,21,MIN(21,MAX(1,ROUNDUP(4*Z25,0)))) -> 15 | AL25: =IF(pd_annual=0,21,MIN(21,MAX(1,ROUNDUP(4*AA25,0)))) -> 20 | AM25: =IF(pd_annual=0,21,MIN(21,MAX(1,ROUNDUP(4*AB25,0)))) -> 21 | AN25: =IF(pd_annual=0,21,MIN(21,MAX(1,ROUNDUP(4*AC25,0)))) -> 21 | AO25: =IF(pd_annual=0,21,MIN(21,MAX(1,ROUNDUP(4*AD25,0)))) -> 21 | AP25: =IF(pd_annual=0,21,MIN(21,MAX(1,ROUNDUP(4*AE25,0)))) -> 21 | ... AR25: =IF(pd_annual=0,21,MIN(21,MAX(1,ROUNDUP(4*AG25,0)))) -> 21 | AT25: =COUNTIF($AI25:$AR25,"<=20") -> 2
A26: 9 | B26: =SUMPRODUCT(Random!$B26:$K26,$B$4:$K$4) -> -0.17451781 | C26: =SUMPRODUCT(Random!$B26:$K26,$B$5:$K$5) -> -0.94143933 | D26: =SUMPRODUCT(Random!$B26:$K26,$B$6:$K$6) -> 0.81121802 | E26: =SUMPRODUCT(Random!$B26:$K26,$B$7:$K$7) -> -0.2760571 | F26: =SUMPRODUCT(Random!$B26:$K26,$B$8:$K$8) -> 0.53736771 | G26: =SUMPRODUCT(Random!$B26:$K26,$B$9:$K$9) -> -0.084320087 | H26: =SUMPRODUCT(Random!$B26:$K26,$B$10:$K$10) -> -0.45726745 | I26: =SUMPRODUCT(Random!$B26:$K26,$B$11:$K$11) -> -0.20372295 | J26: =SUMPRODUCT(Random!$B26:$K26,$B$12:$K$12) -> -1.2350304 | K26: =SUMPRODUCT(Random!$B26:$K26,$B$13:$K$13) -> 1.2899682 | M26: =NORMSDIST(B26) -> 0.43072927 | N26: =NORMSDIST(C26) -> 0.17323988 | O26: =NORMSDIST(D26) -> 0.79137976 | P26: =NORMSDIST(E26) -> 0.39125211 | Q26: =NORMSDIST(F26) -> 0.70449318 | R26: =NORMSDIST(G26) -> 0.46640097 | S26: =NORMSDIST(H26) -> 0.32373941 | T26: =NORMSDIST(I26) -> 0.419285 | ... V26: =NORMSDIST(K26) -> 0.90146916 | X26: =IF(pd_annual=0,"never",LN(1-M26)/LN(1-pd_annual)) -> 13.801363 | Y26: =IF(pd_annual=0,"never",LN(1-N26)/LN(1-pd_annual)) -> 4.6602497 | Z26: =IF(pd_annual=0,"never",LN(1-O26)/LN(1-pd_annual)) -> 38.392042 | AA26: =IF(pd_annual=0,"never",LN(1-P26)/LN(1-pd_annual)) -> 12.158913 | AB26: =IF(pd_annual=0,"never",LN(1-Q26)/LN(1-pd_annual)) -> 29.862905 | AC26: =IF(pd_annual=0,"never",LN(1-R26)/LN(1-pd_annual)) -> 15.386573 | AD26: =IF(pd_annual=0,"never",LN(1-S26)/LN(1-pd_annual)) -> 9.5825006 | AE26: =IF(pd_annual=0,"never",LN(1-T26)/LN(1-pd_annual)) -> 13.313783 | ... AG26: =IF(pd_annual=0,"never",LN(1-V26)/LN(1-pd_annual)) -> 56.768065 | AI26: =IF(pd_annual=0,21,MIN(21,MAX(1,ROUNDUP(4*X26,0)))) -> 21 | AJ26: =IF(pd_annual=0,21,MIN(21,MAX(1,ROUNDUP(4*Y26,0)))) -> 19 | AK26: =IF(pd_annual=0,21,MIN(21,MAX(1,ROUNDUP(4*Z26,0)))) -> 21 | AL26: =IF(pd_annual=0,21,MIN(21,MAX(1,ROUNDUP(4*AA26,0)))) -> 21 | AM26: =IF(pd_annual=0,21,MIN(21,MAX(1,ROUNDUP(4*AB26,0)))) -> 21 | AN26: =IF(pd_annual=0,21,MIN(21,MAX(1,ROUNDUP(4*AC26,0)))) -> 21 | AO26: =IF(pd_annual=0,21,MIN(21,MAX(1,ROUNDUP(4*AD26,0)))) -> 21 | AP26: =IF(pd_annual=0,21,MIN(21,MAX(1,ROUNDUP(4*AE26,0)))) -> 21 | ... AR26: =IF(pd_annual=0,21,MIN(21,MAX(1,ROUNDUP(4*AG26,0)))) -> 21 | AT26: =COUNTIF($AI26:$AR26,"<=20") -> 2
A27: 10 | B27: =SUMPRODUCT(Random!$B27:$K27,$B$4:$K$4) -> 1.2427491 | C27: =SUMPRODUCT(Random!$B27:$K27,$B$5:$K$5) -> -0.98149066 | D27: =SUMPRODUCT(Random!$B27:$K27,$B$6:$K$6) -> 1.0923117 | E27: =SUMPRODUCT(Random!$B27:$K27,$B$7:$K$7) -> -0.67953219 | F27: =SUMPRODUCT(Random!$B27:$K27,$B$8:$K$8) -> 0.10966455 | G27: =SUMPRODUCT(Random!$B27:$K27,$B$9:$K$9) -> 1.6829944 | H27: =SUMPRODUCT(Random!$B27:$K27,$B$10:$K$10) -> 2.0018798 | I27: =SUMPRODUCT(Random!$B27:$K27,$B$11:$K$11) -> 0.5981282 | J27: =SUMPRODUCT(Random!$B27:$K27,$B$12:$K$12) -> 1.4173732 | K27: =SUMPRODUCT(Random!$B27:$K27,$B$13:$K$13) -> 1.0848986 | M27: =NORMSDIST(B27) -> 0.89301985 | N27: =NORMSDIST(C27) -> 0.16317542 | O27: =NORMSDIST(D27) -> 0.86265194 | P27: =NORMSDIST(E27) -> 0.24840036 | Q27: =NORMSDIST(F27) -> 0.54366229 | R27: =NORMSDIST(G27) -> 0.95381192 | S27: =NORMSDIST(H27) -> 0.97735117 | T27: =NORMSDIST(I27) -> 0.7251228 | ... V27: =NORMSDIST(K27) -> 0.86101671 | X27: =IF(pd_annual=0,"never",LN(1-M27)/LN(1-pd_annual)) -> 54.75264 | Y27: =IF(pd_annual=0,"never",LN(1-N27)/LN(1-pd_annual)) -> 4.3638439 | Z27: =IF(pd_annual=0,"never",LN(1-O27)/LN(1-pd_annual)) -> 48.631552 | AA27: =IF(pd_annual=0,"never",LN(1-P27)/LN(1-pd_annual)) -> 6.9950401 | AB27: =IF(pd_annual=0,"never",LN(1-Q27)/LN(1-pd_annual)) -> 19.218124 | AC27: =IF(pd_annual=0,"never",LN(1-R27)/LN(1-pd_annual)) -> 75.327859 | AD27: =IF(pd_annual=0,"never",LN(1-S27)/LN(1-pd_annual)) -> 92.784467 | AE27: =IF(pd_annual=0,"never",LN(1-T27)/LN(1-pd_annual)) -> 31.635662 | ... AG27: =IF(pd_annual=0,"never",LN(1-V27)/LN(1-pd_annual)) -> 48.341625 | AI27: =IF(pd_annual=0,21,MIN(21,MAX(1,ROUNDUP(4*X27,0)))) -> 21 | AJ27: =IF(pd_annual=0,21,MIN(21,MAX(1,ROUNDUP(4*Y27,0)))) -> 18 | AK27: =IF(pd_annual=0,21,MIN(21,MAX(1,ROUNDUP(4*Z27,0)))) -> 21 | AL27: =IF(pd_annual=0,21,MIN(21,MAX(1,ROUNDUP(4*AA27,0)))) -> 21 | AM27: =IF(pd_annual=0,21,MIN(21,MAX(1,ROUNDUP(4*AB27,0)))) -> 21 | AN27: =IF(pd_annual=0,21,MIN(21,MAX(1,ROUNDUP(4*AC27,0)))) -> 21 | AO27: =IF(pd_annual=0,21,MIN(21,MAX(1,ROUNDUP(4*AD27,0)))) -> 21 | AP27: =IF(pd_annual=0,21,MIN(21,MAX(1,ROUNDUP(4*AE27,0)))) -> 21 | ... AR27: =IF(pd_annual=0,21,MIN(21,MAX(1,ROUNDUP(4*AG27,0)))) -> 21 | AT27: =COUNTIF($AI27:$AR27,"<=20") -> 1
A28: 11 | B28: =SUMPRODUCT(Random!$B28:$K28,$B$4:$K$4) -> -0.36636517 | C28: =SUMPRODUCT(Random!$B28:$K28,$B$5:$K$5) -> 0.55164958 | D28: =SUMPRODUCT(Random!$B28:$K28,$B$6:$K$6) -> 0.82970937 | E28: =SUMPRODUCT(Random!$B28:$K28,$B$7:$K$7) -> -0.12008925 | F28: =SUMPRODUCT(Random!$B28:$K28,$B$8:$K$8) -> 1.1141977 | G28: =SUMPRODUCT(Random!$B28:$K28,$B$9:$K$9) -> 2.3038175 | H28: =SUMPRODUCT(Random!$B28:$K28,$B$10:$K$10) -> -0.1605031 | I28: =SUMPRODUCT(Random!$B28:$K28,$B$11:$K$11) -> 0.66320194 | J28: =SUMPRODUCT(Random!$B28:$K28,$B$12:$K$12) -> -0.43753035 | K28: =SUMPRODUCT(Random!$B28:$K28,$B$13:$K$13) -> 0.49609053 | M28: =NORMSDIST(B28) -> 0.3570463 | N28: =NORMSDIST(C28) -> 0.70940577 | O28: =NORMSDIST(D28) -> 0.79664844 | P28: =NORMSDIST(E28) -> 0.45220622 | Q28: =NORMSDIST(F28) -> 0.86740281 | R28: =NORMSDIST(G28) -> 0.98938356 | S28: =NORMSDIST(H28) -> 0.43624239 | T28: =NORMSDIST(I28) -> 0.74639939 | ... V28: =NORMSDIST(K28) -> 0.69008473 | X28: =IF(pd_annual=0,"never",LN(1-M28)/LN(1-pd_annual)) -> 10.819721 | Y28: =IF(pd_annual=0,"never",LN(1-N28)/LN(1-pd_annual)) -> 30.273567 | Z28: =IF(pd_annual=0,"never",LN(1-O28)/LN(1-pd_annual)) -> 39.018646 | AA28: =IF(pd_annual=0,"never",LN(1-P28)/LN(1-pd_annual)) -> 14.743434 | AB28: =IF(pd_annual=0,"never",LN(1-Q28)/LN(1-pd_annual)) -> 49.493891 | AC28: =IF(pd_annual=0,"never",LN(1-R28)/LN(1-pd_annual)) -> 111.34564 | AD28: =IF(pd_annual=0,"never",LN(1-S28)/LN(1-pd_annual)) -> 14.039757 | AE28: =IF(pd_annual=0,"never",LN(1-T28)/LN(1-pd_annual)) -> 33.609201 | ... AG28: =IF(pd_annual=0,"never",LN(1-V28)/LN(1-pd_annual)) -> 28.696695 | AI28: =IF(pd_annual=0,21,MIN(21,MAX(1,ROUNDUP(4*X28,0)))) -> 21 | AJ28: =IF(pd_annual=0,21,MIN(21,MAX(1,ROUNDUP(4*Y28,0)))) -> 21 | AK28: =IF(pd_annual=0,21,MIN(21,MAX(1,ROUNDUP(4*Z28,0)))) -> 21 | AL28: =IF(pd_annual=0,21,MIN(21,MAX(1,ROUNDUP(4*AA28,0)))) -> 21 | AM28: =IF(pd_annual=0,21,MIN(21,MAX(1,ROUNDUP(4*AB28,0)))) -> 21 | AN28: =IF(pd_annual=0,21,MIN(21,MAX(1,ROUNDUP(4*AC28,0)))) -> 21 | AO28: =IF(pd_annual=0,21,MIN(21,MAX(1,ROUNDUP(4*AD28,0)))) -> 21 | AP28: =IF(pd_annual=0,21,MIN(21,MAX(1,ROUNDUP(4*AE28,0)))) -> 21 | ... AR28: =IF(pd_annual=0,21,MIN(21,MAX(1,ROUNDUP(4*AG28,0)))) -> 21 | AT28: =COUNTIF($AI28:$AR28,"<=20") -> 0
A29: 12 | B29: =SUMPRODUCT(Random!$B29:$K29,$B$4:$K$4) -> 0.99133786 | C29: =SUMPRODUCT(Random!$B29:$K29,$B$5:$K$5) -> 0.71200016 | D29: =SUMPRODUCT(Random!$B29:$K29,$B$6:$K$6) -> -0.27248139 | E29: =SUMPRODUCT(Random!$B29:$K29,$B$7:$K$7) -> 0.0036128625 | F29: =SUMPRODUCT(Random!$B29:$K29,$B$8:$K$8) -> 1.6503256 | G29: =SUMPRODUCT(Random!$B29:$K29,$B$9:$K$9) -> 1.5415735 | H29: =SUMPRODUCT(Random!$B29:$K29,$B$10:$K$10) -> 0.49146658 | I29: =SUMPRODUCT(Random!$B29:$K29,$B$11:$K$11) -> -0.48240188 | J29: =SUMPRODUCT(Random!$B29:$K29,$B$12:$K$12) -> -0.073073472 | K29: =SUMPRODUCT(Random!$B29:$K29,$B$13:$K$13) -> -1.5878721 | M29: =NORMSDIST(B29) -> 0.83923968 | N29: =NORMSDIST(C29) -> 0.76176766 | O29: =NORMSDIST(D29) -> 0.39262595 | P29: =NORMSDIST(E29) -> 0.50144132 | Q29: =NORMSDIST(F29) -> 0.95056182 | R29: =NORMSDIST(G29) -> 0.93841137 | S29: =NORMSDIST(H29) -> 0.68845176 | T29: =NORMSDIST(I29) -> 0.31476024 | ... V29: =NORMSDIST(K29) -> 0.05615763 | X29: =IF(pd_annual=0,"never",LN(1-M29)/LN(1-pd_annual)) -> 44.77588 | Y29: =IF(pd_annual=0,"never",LN(1-N29)/LN(1-pd_annual)) -> 35.140587 | Z29: =IF(pd_annual=0,"never",LN(1-O29)/LN(1-pd_annual)) -> 12.21426 | AA29: =IF(pd_annual=0,"never",LN(1-P29)/LN(1-pd_annual)) -> 17.050465 | AB29: =IF(pd_annual=0,"never",LN(1-Q29)/LN(1-pd_annual)) -> 73.662061 | AC29: =IF(pd_annual=0,"never",LN(1-R29)/LN(1-pd_annual)) -> 68.278829 | AD29: =IF(pd_annual=0,"never",LN(1-S29)/LN(1-pd_annual)) -> 28.567959 | AE29: =IF(pd_annual=0,"never",LN(1-T29)/LN(1-pd_annual)) -> 9.2593833 | ... AG29: =IF(pd_annual=0,"never",LN(1-V29)/LN(1-pd_annual)) -> 1.415808 | AI29: =IF(pd_annual=0,21,MIN(21,MAX(1,ROUNDUP(4*X29,0)))) -> 21 | AJ29: =IF(pd_annual=0,21,MIN(21,MAX(1,ROUNDUP(4*Y29,0)))) -> 21 | AK29: =IF(pd_annual=0,21,MIN(21,MAX(1,ROUNDUP(4*Z29,0)))) -> 21 | AL29: =IF(pd_annual=0,21,MIN(21,MAX(1,ROUNDUP(4*AA29,0)))) -> 21 | AM29: =IF(pd_annual=0,21,MIN(21,MAX(1,ROUNDUP(4*AB29,0)))) -> 21 | AN29: =IF(pd_annual=0,21,MIN(21,MAX(1,ROUNDUP(4*AC29,0)))) -> 21 | AO29: =IF(pd_annual=0,21,MIN(21,MAX(1,ROUNDUP(4*AD29,0)))) -> 21 | AP29: =IF(pd_annual=0,21,MIN(21,MAX(1,ROUNDUP(4*AE29,0)))) -> 21 | ... AR29: =IF(pd_annual=0,21,MIN(21,MAX(1,ROUNDUP(4*AG29,0)))) -> 6 | AT29: =COUNTIF($AI29:$AR29,"<=20") -> 1
